2018-06-26 21:41:30,812 [        MainThread][         start][    INFO] Starting TheRaidMap
2018-06-26 21:41:30,813 [        MainThread][       _legacy][    INFO] Starting factory <client.VNCDoToolFactory instance at 0x10a957ab8>
2018-06-26 21:41:30,999 [            VNCPic][       _legacy][    INFO] Using protocol version 3.800
2018-06-26 21:41:31,113 [            VNCPic][       _legacy][    INFO] Cannot connect password check failed!
2018-06-26 21:41:31,114 [            VNCPic][       _legacy][    INFO] Stopping factory <client.VNCDoToolFactory instance at 0x10a957ab8>
2018-06-26 21:41:40,814 [        MainThread][         start][   ERROR] Uncaught exception
Traceback (most recent call last):
  File "start.py", line 101, in <module>
    main()
  File "start.py", line 65, in main
    getVNCPic()
  File "/Users/fameitelhuber/Desktop/TheRaidMapper/getVNCPic.py", line 166, in getVNCPic
    client1.captureScreen('screenshot.png')
  File "/Users/fameitelhuber/Desktop/TheRaidMapper/getVNCPic.py", line 105, in proxy_call
    raise TimeoutError("Timeout while waiting for client response")
TimeoutError: Timeout while waiting for client response
